<?xml version="1.0" ?>
<robot name="panda">
	<link name="world">
		<inertial>
			<origin rpy="0.00000 -0.00000 0.00000" xyz="0.00000 0.00000 0.00000"/>
			<mass value="0.00000"/>
			<inertia ixx="0.00000" ixy="0" ixz="0" iyy="0.00000" iyz="0" izz="0.00000"/>
		</inertial>
	</link>
	<link name="fixed_base">
		<inertial>
			<origin rpy="0.00000 -0.00000 0.00000" xyz="0.00000 0.00000 0.05000"/>
			<mass value="2.90000"/>
			<inertia ixx="0.01470" ixy="0" ixz="0" iyy="0.01849" iyz="0" izz="0.02260"/>
		</inertial>
		<visual>
			<origin rpy="0.00000 -0.00000 0.00000" xyz="0.00000 0.00000 0.00000"/>
			<geometry>
				<mesh filename="../robot_arm_assets/franka_panda/urdfs/../collision/link0.obj" scale="1.00000 1.00000 1.00000"/>
			</geometry>
			<material name="mat_0">
				<color rgba="1.00000 1.00000 1.00000 1.00000" />
			</material>
		</visual>
		<collision>
			<origin rpy="0.00000 -0.00000 0.00000" xyz="0.00000 0.00000 0.00000"/>
			<geometry>
				<mesh filename="../robot_arm_assets/franka_panda/urdfs/../collision/link0.obj" scale="1.00000 1.00000 1.00000"/>
			</geometry>
		</collision>
	</link>
	<link name="panda_link1">
		<inertial>
			<origin rpy="0.00000 -0.00000 0.00000" xyz="0.00000 -0.04000 -0.05000"/>
			<mass value="2.70000"/>
			<inertia ixx="0.02297" ixy="0" ixz="0" iyy="0.01777" iyz="0" izz="0.01148"/>
		</inertial>
		<visual>
			<origin rpy="0.00000 -0.00000 0.00000" xyz="0.00000 0.00000 0.00000"/>
			<geometry>
				<mesh filename="../robot_arm_assets/franka_panda/visual/link1.obj" scale="1.00000 1.00000 1.00000"/>
			</geometry>
			<material name="mat_1">
				<color rgba="1.00000 1.00000 1.00000 1.00000" />
			</material>
		</visual>
		<collision>
			<origin rpy="0.00000 -0.00000 0.00000" xyz="0.00000 0.00000 0.00000"/>
			<geometry>
				<mesh filename="../robot_arm_assets/franka_panda/urdfs/../collision/link1.obj" scale="1.00000 1.00000 1.00000"/>
			</geometry>
		</collision>
	</link>
	<link name="panda_link2">
		<inertial>
			<origin rpy="0.00000 -0.00000 0.00000" xyz="0.00000 -0.04000 0.06000"/>
			<mass value="2.73000"/>
			<inertia ixx="0.02349" ixy="0" ixz="0" iyy="0.01161" iyz="0" izz="0.01823"/>
		</inertial>
		<visual>
			<origin rpy="0.00000 -0.00000 0.00000" xyz="0.00000 0.00000 0.00000"/>
			<geometry>
				<mesh filename="../robot_arm_assets/franka_panda/visual/link2.obj" scale="1.00000 1.00000 1.00000"/>
			</geometry>
			<material name="mat_2">
				<color rgba="1.00000 1.00000 1.00000 1.00000" />
			</material>
		</visual>
		<collision>
			<origin rpy="0.00000 -0.00000 0.00000" xyz="0.00000 0.00000 0.00000"/>
			<geometry>
				<mesh filename="../robot_arm_assets/franka_panda/urdfs/../collision/link2.obj" scale="1.00000 1.00000 1.00000"/>
			</geometry>
		</collision>
	</link>
	<link name="panda_link3">
		<inertial>
			<origin rpy="0.00000 -0.00000 0.00000" xyz="0.01000 0.01000 -0.05000"/>
			<mass value="2.04000"/>
			<inertia ixx="0.01092" ixy="0" ixz="0" iyy="0.01258" iyz="0" izz="0.01197"/>
		</inertial>
		<visual>
			<origin rpy="0.00000 -0.00000 0.00000" xyz="0.00000 0.00000 0.00000"/>
			<geometry>
				<mesh filename="../robot_arm_assets/franka_panda/visual/link3.obj" scale="1.00000 1.00000 1.00000"/>
			</geometry>
			<material name="mat_3">
				<color rgba="1.00000 1.00000 1.00000 1.00000" />
			</material>
		</visual>
		<collision>
			<origin rpy="0.00000 -0.00000 0.00000" xyz="0.00000 0.00000 0.00000"/>
			<geometry>
				<mesh filename="../robot_arm_assets/franka_panda/urdfs/../collision/link3.obj" scale="1.00000 1.00000 1.00000"/>
			</geometry>
		</collision>
	</link>
	<link name="panda_link4">
		<inertial>
			<origin rpy="0.00000 -0.00000 0.00000" xyz="-0.03000 0.03000 0.02000"/>
			<mass value="2.08000"/>
			<inertia ixx="0.01134" ixy="0" ixz="0" iyy="0.01225" iyz="0" izz="0.01306"/>
		</inertial>
		<visual>
			<origin rpy="0.00000 -0.00000 0.00000" xyz="0.00000 0.00000 0.00000"/>
			<geometry>
				<mesh filename="../robot_arm_assets/franka_panda/visual/link4.obj" scale="1.00000 1.00000 1.00000"/>
			</geometry>
			<material name="mat_4">
				<color rgba="1.00000 1.00000 1.00000 1.00000" />
			</material>
		</visual>
		<collision>
			<origin rpy="0.00000 -0.00000 0.00000" xyz="0.00000 0.00000 0.00000"/>
			<geometry>
				<mesh filename="../robot_arm_assets/franka_panda/urdfs/../collision/link4.obj" scale="1.00000 1.00000 1.00000"/>
			</geometry>
		</collision>
	</link>
	<link name="panda_link5">
		<inertial>
			<origin rpy="0.00000 -0.00000 0.00000" xyz="0.00000 0.04000 -0.12000"/>
			<mass value="3.00000"/>
			<inertia ixx="0.03568" ixy="0" ixz="0" iyy="0.02985" iyz="0" izz="0.01280"/>
		</inertial>
		<visual>
			<origin rpy="0.00000 -0.00000 0.00000" xyz="0.00000 0.00000 0.00000"/>
			<geometry>
				<mesh filename="../robot_arm_assets/franka_panda/visual/link5.obj" scale="1.00000 1.00000 1.00000"/>
			</geometry>
			<material name="mat_5">
				<color rgba="1.00000 1.00000 1.00000 1.00000" />
			</material>
		</visual>
		<collision>
			<origin rpy="0.00000 -0.00000 0.00000" xyz="0.00000 0.00000 0.00000"/>
			<geometry>
				<mesh filename="../robot_arm_assets/franka_panda/urdfs/../collision/link5.obj" scale="1.00000 1.00000 1.00000"/>
			</geometry>
		</collision>
	</link>
	<link name="panda_link6">
		<inertial>
			<origin rpy="0.00000 -0.00000 0.00000" xyz="0.04000 0.00000 0.00000"/>
			<mass value="1.30000"/>
			<inertia ixx="0.00343" ixy="0" ixz="0" iyy="0.00512" iyz="0" izz="0.00599"/>
		</inertial>
		<visual>
			<origin rpy="0.00000 -0.00000 0.00000" xyz="0.00000 0.00000 0.00000"/>
			<geometry>
				<mesh filename="../robot_arm_assets/franka_panda/visual/link6.obj" scale="1.00000 1.00000 1.00000"/>
			</geometry>
			<material name="mat_6">
				<color rgba="1.00000 1.00000 1.00000 1.00000" />
			</material>
		</visual>
		<collision>
			<origin rpy="0.00000 -0.00000 0.00000" xyz="0.00000 0.00000 0.00000"/>
			<geometry>
				<mesh filename="../robot_arm_assets/franka_panda/urdfs/../collision/link6.obj" scale="1.00000 1.00000 1.00000"/>
			</geometry>
		</collision>
	</link>
	<link name="panda_link7">
		<inertial>
			<origin rpy="0.00000 -0.00000 0.00000" xyz="0.00000 0.00000 0.08000"/>
			<mass value="0.20000"/>
			<inertia ixx="0.00036" ixy="0" ixz="0" iyy="0.00036" iyz="0" izz="0.00059"/>
		</inertial>
		<visual>
			<origin rpy="0.00000 -0.00000 0.00000" xyz="0.00000 0.00000 0.00000"/>
			<geometry>
				<mesh filename="../robot_arm_assets/franka_panda/urdfs/../collision/link7.obj" scale="1.00000 1.00000 1.00000"/>
			</geometry>
			<material name="mat_7">
				<color rgba="1.00000 1.00000 1.00000 1.00000" />
			</material>
		</visual>
		<collision>
			<origin rpy="0.00000 -0.00000 0.00000" xyz="0.00000 0.00000 0.00000"/>
			<geometry>
				<mesh filename="../robot_arm_assets/franka_panda/urdfs/../collision/link7.obj" scale="1.00000 1.00000 1.00000"/>
			</geometry>
		</collision>
	</link>
	<link name="ee_link">
		<inertial>
			<origin rpy="-3.14000 -0.00000 1.57000" xyz="0.00000 0.00000 0.00000"/>
			<mass value="0.00000"/>
			<inertia ixx="0.00000" ixy="0" ixz="0" iyy="0.00000" iyz="0" izz="0.00000"/>
		</inertial>
		<visual>
			<origin rpy="0.00000 -0.00000 0.00000" xyz="0.00000 0.00000 0.00000"/>
			<geometry>
				<sphere radius="0.00100"/>
			</geometry>
			<material name="mat_8">
				<color rgba="1.00000 0.00000 0.00000 1.00000" />
			</material>
		</visual>
		<collision>
			<origin rpy="0.00000 -0.00000 0.00000" xyz="0.00000 0.00000 0.00000"/>
			<geometry>
				<sphere radius="0.00100"/>
			</geometry>
		</collision>
	</link>
	<link name="tactip_body_link">
		<inertial>
			<origin rpy="0.00000 -0.00000 0.00000" xyz="0.00000 0.00000 0.00000"/>
			<mass value="0.25000"/>
			<inertia ixx="0.00010" ixy="0" ixz="0" iyy="0.00010" iyz="0" izz="0.00013"/>
		</inertial>
		<visual>
			<origin rpy="0.00000 -0.00000 0.00000" xyz="0.00000 0.00000 0.00000"/>
			<geometry>
				<mesh filename="../sensor_assets/mini_tactip/body/minitip_body.obj" scale="1.00000 1.00000 1.00000"/>
			</geometry>
			<material name="mat_9">
				<color rgba="0.80000 0.80000 0.80000 1.00000" />
			</material>
		</visual>
		<collision>
			<origin rpy="0.00000 -0.00000 0.00000" xyz="0.00000 0.00000 0.00000"/>
			<geometry>
				<mesh filename="../sensor_assets/mini_tactip/body/minitip_body.obj" scale="1.00000 1.00000 1.00000"/>
			</geometry>
		</collision>
	</link>
	<link name="tactip_tip_link">
		<inertial>
			<origin rpy="0.00000 -0.00000 0.00000" xyz="0.00000 0.00000 0.00000"/>
			<mass value="0.01000"/>
			<inertia ixx="0.00000" ixy="0" ixz="0" iyy="0.00000" iyz="0" izz="0.00000"/>
		</inertial>
		<visual>
			<origin rpy="0.00000 -0.00000 0.00000" xyz="0.00000 0.00000 0.00000"/>
			<geometry>
				<mesh filename="../sensor_assets/mini_tactip/tip/skin.obj" scale="1.00000 1.00000 1.00000"/>
			</geometry>
			<material name="mat_10">
				<color rgba="0.00000 0.00000 0.00000 1.00000" />
			</material>
		</visual>
		<collision>
			<origin rpy="0.00000 -0.00000 0.00000" xyz="0.00000 0.00000 0.00000"/>
			<geometry>
				<mesh filename="../sensor_assets/mini_tactip/tip/core.obj" scale="1.00000 1.00000 1.00000"/>
			</geometry>
		</collision>
	</link>
	<link name="tcp_link">
		<inertial>
			<origin rpy="0.00000 -0.00000 1.57000" xyz="0.00000 0.00000 0.00000"/>
			<mass value="0.00000"/>
			<inertia ixx="0.00000" ixy="0" ixz="0" iyy="0.00000" iyz="0" izz="0.00000"/>
		</inertial>
		<visual>
			<origin rpy="0.00000 -0.00000 0.00000" xyz="0.00000 0.00000 0.00000"/>
			<geometry>
				<sphere radius="0.00100"/>
			</geometry>
			<material name="mat_11">
				<color rgba="0.90000 0.00000 0.20000 0.50000" />
			</material>
		</visual>
	</link>
	<joint name="world_joint" type="fixed">
		<parent link="world"/>
		<child link="fixed_base"/>
		<dynamics damping="1.0" friction="0.0001"/>
		<origin rpy="0.00000 -0.00000 -3.14000" xyz="0.00000 0.00000 0.00000"/>
		<axis xyz="0.00000 0.00000 0.00000"/>
	</joint>
	<joint name="panda_joint1" type="revolute">
		<parent link="fixed_base"/>
		<child link="panda_link1"/>
		<limit effort="87.00000" lower="-100.00000" upper="100.00000" velocity="2.17500"/>
		<dynamics damping="1.0" friction="0.0001"/>
		<origin rpy="0.00000 -0.00000 0.00000" xyz="0.00000 0.00000 0.33300"/>
		<axis xyz="0.00000 0.00000 1.00000"/>
	</joint>
	<joint name="panda_joint2" type="revolute">
		<parent link="panda_link1"/>
		<child link="panda_link2"/>
		<limit effort="87.00000" lower="-100.00000" upper="100.00000" velocity="2.17500"/>
		<dynamics damping="1.0" friction="0.0001"/>
		<origin rpy="-1.57080 0.00000 0.00000" xyz="0.00000 0.00000 0.00000"/>
		<axis xyz="0.00000 0.00000 1.00000"/>
	</joint>
	<joint name="panda_joint3" type="revolute">
		<parent link="panda_link2"/>
		<child link="panda_link3"/>
		<limit effort="87.00000" lower="-100.00000" upper="100.00000" velocity="2.17500"/>
		<dynamics damping="1.0" friction="0.0001"/>
		<origin rpy="1.57080 -0.00000 0.00000" xyz="0.00000 -0.31600 0.00000"/>
		<axis xyz="0.00000 0.00000 1.00000"/>
	</joint>
	<joint name="panda_joint4" type="revolute">
		<parent link="panda_link3"/>
		<child link="panda_link4"/>
		<limit effort="87.00000" lower="-100.00000" upper="100.00000" velocity="2.17500"/>
		<dynamics damping="1.0" friction="0.0001"/>
		<origin rpy="1.57080 -0.00000 0.00000" xyz="0.08250 0.00000 0.00000"/>
		<axis xyz="0.00000 0.00000 1.00000"/>
	</joint>
	<joint name="panda_joint5" type="revolute">
		<parent link="panda_link4"/>
		<child link="panda_link5"/>
		<limit effort="12.00000" lower="-100.00000" upper="100.00000" velocity="2.61000"/>
		<dynamics damping="1.0" friction="0.0001"/>
		<origin rpy="-1.57080 0.00000 0.00000" xyz="-0.08250 0.38400 0.00000"/>
		<axis xyz="0.00000 0.00000 1.00000"/>
	</joint>
	<joint name="panda_joint6" type="revolute">
		<parent link="panda_link5"/>
		<child link="panda_link6"/>
		<limit effort="12.00000" lower="-100.00000" upper="100.00000" velocity="2.61000"/>
		<dynamics damping="1.0" friction="0.0001"/>
		<origin rpy="1.57080 -0.00000 0.00000" xyz="0.00000 0.00000 0.00000"/>
		<axis xyz="0.00000 0.00000 1.00000"/>
	</joint>
	<joint name="panda_joint7" type="revolute">
		<parent link="panda_link6"/>
		<child link="panda_link7"/>
		<limit effort="12.00000" lower="-100.00000" upper="100.00000" velocity="2.61000"/>
		<dynamics damping="1.0" friction="0.0001"/>
		<origin rpy="1.57080 -0.00000 0.00000" xyz="0.08800 0.00000 0.00000"/>
		<axis xyz="0.00000 0.00000 1.00000"/>
	</joint>
	<joint name="ee_joint" type="fixed">
		<parent link="panda_link7"/>
		<child link="ee_link"/>
		<dynamics damping="1.0" friction="0.0001"/>
		<origin rpy="3.14000 -0.00000 1.57000" xyz="0.00000 0.00000 0.10700"/>
		<axis xyz="0.00000 0.00000 0.00000"/>
	</joint>
	<joint name="joint_dummy1" type="fixed">
		<parent link="ee_link"/>
		<child link="tactip_body_link"/>
		<dynamics damping="1.0" friction="0.0001"/>
		<origin rpy="-3.14159 0.00000 3.14159" xyz="0.00000 0.00000 0.00000"/>
		<axis xyz="0.00000 0.00000 1.00000"/>
	</joint>
	<joint name="tactip_tip_to_body" type="fixed">
		<parent link="tactip_body_link"/>
		<child link="tactip_tip_link"/>
		<dynamics damping="1.0" friction="0.0001"/>
		<origin rpy="1.57000 -0.00000 0.00000" xyz="0.00000 0.00000 0.03500"/>
		<axis xyz="0.00000 0.00000 0.00000"/>
	</joint>
	<joint name="tcp_joint" type="fixed">
		<parent link="tactip_body_link"/>
		<child link="tcp_link"/>
		<dynamics damping="1.0" friction="0.0001"/>
		<origin rpy="0.00000 -0.00000 0.00000" xyz="0.00000 0.00000 0.05500"/>
		<axis xyz="0.00000 0.00000 0.00000"/>
	</joint>
</robot>
